Workbook

Sheet 設備清單總覽
A1: 中央空調系統 電控 I/O 點位規劃 — 設備清單總覽
A2: 依「中央空調系統電控系統規劃企劃書」(0909) 展開；實際數量與型號以詳細設計定案為準
A4: 設備區域代碼 | B4: 設備名稱 | C4: 建議數量 | D4: 主要功能 | E4: 控制方式 | F4: 手動模式 | G4: 自動模式 | H4: 備註
A5: CH | B5: 冰水主機 (永磁變頻螺旋水冷滿液式) | C5: 1台(預留擴充至2台) | D5: 製冷主機，機組內建PLC/HMI自行調節製冷能力 | E5: 機組內建PLC自動運轉；現場MCC-PLC僅下達啟停指令，不介入機組內部迴路 | F5: 機組面板HMI可切至機側控制（原廠書面同意前不可任意更改內部接線） | G5: MCC-PLC依連鎖程序遠端啟停；製冷能力調節仍由機組自身PLC/變頻器控制 | H5: PLC故障時可手動切換機械模式運轉(原廠功能)
A6: CT | B6: 冷卻水塔風扇 | C6: 2台(1用1備，變頻) | D6: 冷卻水散熱，依回水溫度變頻調整轉速 | E6: 現場手動/自動(HOA)選擇開關 + VFD | F6: 盤面或VFD面板手動啟停，不經PLC連鎖邏輯（保護連鎖仍需生效） | G6: PLC依冷卻水回水溫度/外氣濕球溫度自動調整頻率，達成節能降頻 | H6: 水盤液位開關防止空轉或溢流，兩模式皆需連鎖保護
A7: CHWP | B7: 冰水泵浦 | C7: 2台(1用1備，變頻) | D7: 冰水循環輸送至空調末端(AHU/FCU) | E7: 現場手動/自動(HOA)選擇開關 + VFD | F7: 盤面或VFD面板手動啟停，不經PLC連鎖邏輯（保護連鎖仍需生效） | G7: PLC依定壓差或變流量邏輯自動啟停與調速 | H7: 冰水流量開關保護，異物過濾器避免堵塞
A8: CWP | B8: 冷卻水泵浦 | C8: 2台(1用1備，變頻) | D8: 冷卻水循環輸送至冷卻水塔與冷凝器 | E8: 現場手動/自動(HOA)選擇開關 + VFD | F8: 盤面或VFD面板手動啟停，不經PLC連鎖邏輯（保護連鎖仍需生效） | G8: PLC依冷凝器負荷/壓差自動啟停與調速 | H8: 冷卻水流量開關保護，異物過濾器避免堵塞
A9: MCC | B9: 現場控制盤(MCC)共通點位 | C9: 1面(含PLC/HMI/UPS) | D9: 彙整各設備狀態、執行連鎖邏輯、台數控制與異常保護 | E9: PLC為核心，盤面設系統啟停鈕與緊急停止鈕 | F9: 緊急停止、警報測試等盤面按鈕可直接操作 | G9: PLC依排程/溫度回授/上層SCADA指令執行開機、停機、保護連鎖程序 | H9: PLC/HMI建議加裝UPS，元件配置預留20%以上備用空間
A10: SCADA | B10: SCADA/BAS 中央監控介接 | C10: 1式 | D10: 圖形化監視、歷史趨勢、報表、警報通知、遠端監看操作 | E10: MODBUS TCP 或 BACnet IP 與MCC-PLC通訊 | F10: 依權限可由SCADA端下達手動指令(僅監視/可操作/系統管理分權) | G10: 接收MCC-PLC上傳資料，記錄趨勢與報表，可選配簡訊/E-mail/APP推播 | H10: 操作歷程需留存Audit Trail
A12: 點位數量統計（依 I-O點位明細 分頁自動加總）
A13: 設備區域代碼 | B13: DI | C13: DO | D13: AI | E13: AO | F13: 通訊 | G13: 合計
A14: CH | B14: =COUNTIFS('I-O點位明細'!$B:$B,"CH",'I-O點位明細'!$D:$D,"DI") -> 3 | C14: =COUNTIFS('I-O點位明細'!$B:$B,"CH",'I-O點位明細'!$D:$D,"DO") -> 1 | D14: =COUNTIFS('I-O點位明細'!$B:$B,"CH",'I-O點位明細'!$D:$D,"AI") -> 6 | E14: =COUNTIFS('I-O點位明細'!$B:$B,"CH",'I-O點位明細'!$D:$D,"AO") -> 0 | F14: =COUNTIFS('I-O點位明細'!$B:$B,"CH",'I-O點位明細'!$D:$D,"通訊") -> 1 | G14: =SUM(B14:F14) -> 11
A15: CT | B15: =COUNTIFS('I-O點位明細'!$B:$B,"CT",'I-O點位明細'!$D:$D,"DI") -> 5 | C15: =COUNTIFS('I-O點位明細'!$B:$B,"CT",'I-O點位明細'!$D:$D,"DO") -> 2 | D15: =COUNTIFS('I-O點位明細'!$B:$B,"CT",'I-O點位明細'!$D:$D,"AI") -> 4 | E15: =COUNTIFS('I-O點位明細'!$B:$B,"CT",'I-O點位明細'!$D:$D,"AO") -> 2 | F15: =COUNTIFS('I-O點位明細'!$B:$B,"CT",'I-O點位明細'!$D:$D,"通訊") -> 0 | G15: =SUM(B15:F15) -> 13
A16: CHWP | B16: =COUNTIFS('I-O點位明細'!$B:$B,"CHWP",'I-O點位明細'!$D:$D,"DI") -> 5 | C16: =COUNTIFS('I-O點位明細'!$B:$B,"CHWP",'I-O點位明細'!$D:$D,"DO") -> 2 | D16: =COUNTIFS('I-O點位明細'!$B:$B,"CHWP",'I-O點位明細'!$D:$D,"AI") -> 4 | E16: =COUNTIFS('I-O點位明細'!$B:$B,"CHWP",'I-O點位明細'!$D:$D,"AO") -> 2 | F16: =COUNTIFS('I-O點位明細'!$B:$B,"CHWP",'I-O點位明細'!$D:$D,"通訊") -> 0 | G16: =SUM(B16:F16) -> 13
A17: CWP | B17: =COUNTIFS('I-O點位明細'!$B:$B,"CWP",'I-O點位明細'!$D:$D,"DI") -> 5 | C17: =COUNTIFS('I-O點位明細'!$B:$B,"CWP",'I-O點位明細'!$D:$D,"DO") -> 2 | D17: =COUNTIFS('I-O點位明細'!$B:$B,"CWP",'I-O點位明細'!$D:$D,"AI") -> 4 | E17: =COUNTIFS('I-O點位明細'!$B:$B,"CWP",'I-O點位明細'!$D:$D,"AO") -> 2 | F17: =COUNTIFS('I-O點位明細'!$B:$B,"CWP",'I-O點位明細'!$D:$D,"通訊") -> 0 | G17: =SUM(B17:F17) -> 13
A18: MCC | B18: =COUNTIFS('I-O點位明細'!$B:$B,"MCC",'I-O點位明細'!$D:$D,"DI") -> 3 | C18: =COUNTIFS('I-O點位明細'!$B:$B,"MCC",'I-O點位明細'!$D:$D,"DO") -> 2 | D18: =COUNTIFS('I-O點位明細'!$B:$B,"MCC",'I-O點位明細'!$D:$D,"AI") -> 2 | E18: =COUNTIFS('I-O點位明細'!$B:$B,"MCC",'I-O點位明細'!$D:$D,"AO") -> 0 | F18: =COUNTIFS('I-O點位明細'!$B:$B,"MCC",'I-O點位明細'!$D:$D,"通訊") -> 0 | G18: =SUM(B18:F18) -> 7
A19: SCADA | B19: =COUNTIFS('I-O點位明細'!$B:$B,"SCADA",'I-O點位明細'!$D:$D,"DI") -> 0 | C19: =COUNTIFS('I-O點位明細'!$B:$B,"SCADA",'I-O點位明細'!$D:$D,"DO") -> 0 | D19: =COUNTIFS('I-O點位明細'!$B:$B,"SCADA",'I-O點位明細'!$D:$D,"AI") -> 0 | E19: =COUNTIFS('I-O點位明細'!$B:$B,"SCADA",'I-O點位明細'!$D:$D,"AO") -> 0 | F19: =COUNTIFS('I-O點位明細'!$B:$B,"SCADA",'I-O點位明細'!$D:$D,"通訊") -> 3 | G19: =SUM(B19:F19) -> 3
A20: 總計 | B20: =SUM(B14:B19) -> 21 | C20: =SUM(C14:C19) -> 9 | D20: =SUM(D14:D19) -> 20 | E20: =SUM(E14:E19) -> 6 | F20: =SUM(F14:F19) -> 4 | G20: =SUM(G14:G19) -> 60

Sheet I-O點位明細
A1: 中央空調系統 電控 I/O 點位規劃明細表
A2: ＊點位編號、數量為範例規劃，實際點數應依最終設備數量、感測器配置與SCADA需求於詳細設計階段確認定案
A4: 序號 | B4: 設備區域代碼 | C4: 點位編號 | D4: I/O類型 | E4: 點位名稱 | F4: 訊號型式 | G4: 訊號來源/去向 | H4: 手動模式支援 | I4: 自動模式支援 | J4: 備註
A5: 1 | B5: CH | C5: CH1-DI-01 | D5: DI | E5: 運轉狀態回授 | F5: 無電位接點 | G5: 主機內建控制箱 | H5: 機組面板HMI可監視 | I5: MCC-PLC監視，不介入控制 | J5: 僅監視用途
A6: 2 | B6: CH | C6: CH1-DI-02 | D6: DI | E6: 故障警報接點(綜合) | F6: 無電位接點 | G6: 主機內建控制箱 | H6: 機組面板HMI顯示故障碼 | I6: MCC-PLC監視並觸發連鎖停機 | J6: 含高低壓、防凍、欠相/逆相、過載等綜合故障
A7: 3 | B7: CH | C7: CH1-DI-03 | D7: DI | E7: 機側/遠端控制模式回授 | F7: 無電位接點 | G7: 主機內建控制箱 | H7: 機側控制：僅可由機組面板操作 | I7: 遠端模式：允許MCC-PLC下達啟停指令 | J7: 原廠設定，未經書面同意不得更改機組內部接線
A8: 4 | B8: CH | C8: CH1-DO-01 | D8: DO | E8: 遠端啟動/停止指令 | F8: 24VDC接點或Modbus | G8: 主機內建控制箱 | H8: MCC盤面手動啟停鈕(限機組處於遠端模式時有效) | I8: MCC-PLC依開機/停機程序自動下達 | J8: 機組以變頻軟啟動方式運轉
A9: 5 | B9: CH | C9: CH1-AI-01 | D9: AI | E9: 冰水出水溫度 | F9: Modbus(經通訊讀取) | G9: 主機內建感測器 | H9: 監視 | I9: 監視 | J9: PLC僅讀取，不下達溫度控制迴路
A10: 6 | B10: CH | C10: CH1-AI-02 | D10: AI | E10: 冰水入水溫度 | F10: Modbus(經通訊讀取) | G10: 主機內建感測器 | H10: 監視 | I10: 監視
A11: 7 | B11: CH | C11: CH1-AI-03 | D11: AI | E11: 冷凝器(冷卻水)出水溫度 | F11: Modbus(經通訊讀取) | G11: 主機內建感測器 | H11: 監視 | I11: 監視
A12: 8 | B12: CH | C12: CH1-AI-04 | D12: AI | E12: 冷凝器(冷卻水)入水溫度 | F12: Modbus(經通訊讀取) | G12: 主機內建感測器 | H12: 監視 | I12: 監視
A13: 9 | B13: CH | C13: CH1-AI-05 | D13: AI | E13: 冷媒高/低壓值 | F13: Modbus(經通訊讀取) | G13: 主機內建感測器 | H13: 監視 | I13: 監視 | J13: 供高低壓保護狀態判讀
A14: 10 | B14: CH | C14: CH1-AI-06 | D14: AI | E14: 壓縮機運轉電流/負載率 | F14: Modbus(經通訊讀取) | G14: 主機內建感測器 | H14: 監視 | I14: 監視 | J14: 供COP估算與節能分析
A15: 11 | B15: CH | C15: CH1-COM-01 | D15: 通訊 | E15: 主機PLC/HMI資料整合 | F15: RS-485 MODBUS RTU | G15: 主機內建通訊模組↔MCC-PLC | H15: N/A | I15: 自動讀取全部狀態/溫度/壓力/故障碼 | J15: 選配MODBUS通訊模組後啟用
A16: 12 | B16: CT | C16: CT1-DI-01 | D16: DI | E16: 冷卻水塔風扇#1 手動/自動選擇開關位置 | F16: 無電位接點 | G16: 盤面HOA選擇開關 | H16: 現場手動直接啟停，不經PLC連鎖邏輯 | I16: MCC-PLC自動控制
A17: 13 | B17: CT | C17: CT1-DI-02 | D17: DI | E17: 冷卻水塔風扇#1 運轉/故障回授 | F17: 無電位接點 | G17: 風扇啟動器/VFD | H17: 兩模式皆回授 | I17: 兩模式皆回授
A18: 14 | B18: CT | C18: CT1-DO-01 | D18: DO | E18: 冷卻水塔風扇#1 啟動/停止指令 | F18: 24VDC接點輸出 | G18: 風扇啟動器/VFD | H18: 無效(手動模式下由現場按鈕直接控制) | I18: PLC依連鎖程序下達
A19: 15 | B19: CT | C19: CT1-AI-01 | D19: AI | E19: 冷卻水塔風扇#1 VFD頻率回授 | F19: 4-20mA或Modbus | G19: 變頻器 | H19: 監視 | I19: 監視
A20: 16 | B20: CT | C20: CT1-AI-02 | D20: AI | E20: 冷卻水塔風扇#1 VFD電流回授 | F20: 4-20mA或Modbus | G20: 變頻器 | H20: 監視 | I20: 監視
A21: 17 | B21: CT | C21: CT1-AO-01 | D21: AO | E21: 冷卻水塔風扇#1 VFD頻率指令 | F21: 4-20mA或Modbus | G21: MCC-PLC→變頻器 | H21: 無效(手動模式由VFD面板或盤面旋鈕設定) | I21: PLC依冷卻水回水溫度/濕球溫度自動運算輸出 | J21: 低負載或低濕球溫度時降頻節能
A22: 18 | B22: CT | C22: CT2-DI-01 | D22: DI | E22: 冷卻水塔風扇#2 手動/自動選擇開關位置 | F22: 無電位接點 | G22: 盤面HOA選擇開關 | H22: 現場手動直接啟停，不經PLC連鎖邏輯 | I22: MCC-PLC自動控制
A23: 19 | B23: CT | C23: CT2-DI-02 | D23: DI | E23: 冷卻水塔風扇#2 運轉/故障回授 | F23: 無電位接點 | G23: 風扇啟動器/VFD | H23: 兩模式皆回授 | I23: 兩模式皆回授
A24: 20 | B24: CT | C24: CT2-DO-01 | D24: DO | E24: 冷卻水塔風扇#2 啟動/停止指令 | F24: 24VDC接點輸出 | G24: 風扇啟動器/VFD | H24: 無效(手動模式下由現場按鈕直接控制) | I24: PLC依連鎖程序下達
A25: 21 | B25: CT | C25: CT2-AI-01 | D25: AI | E25: 冷卻水塔風扇#2 VFD頻率回授 | F25: 4-20mA或Modbus | G25: 變頻器 | H25: 監視 | I25: 監視
A26: 22 | B26: CT | C26: CT2-AI-02 | D26: AI | E26: 冷卻水塔風扇#2 VFD電流回授 | F26: 4-20mA或Modbus | G26: 變頻器 | H26: 監視 | I26: 監視
A27: 23 | B27: CT | C27: CT2-AO-01 | D27: AO | E27: 冷卻水塔風扇#2 VFD頻率指令 | F27: 4-20mA或Modbus | G27: MCC-PLC→變頻器 | H27: 無效(手動模式由VFD面板或盤面旋鈕設定) | I27: PLC依冷卻水回水溫度/濕球溫度自動運算輸出 | J27: 低負載或低濕球溫度時降頻節能
A28: 24 | B28: CT | C28: CT-DI-91 | D28: DI | E28: 冷卻水塔水盤液位開關(高/低) | F28: 無電位接點 | G28: 水塔水盤液位開關 | H28: 兩模式皆連鎖生效 | I28: 兩模式皆連鎖生效 | J28: 防止空轉或溢流，保護連鎖不因操作模式而失效
A29: 25 | B29: CHWP | C29: CHWP1-DI-01 | D29: DI | E29: 冰水泵浦#1 手動/自動選擇開關位置 | F29: 無電位接點 | G29: 盤面HOA選擇開關 | H29: 現場手動直接啟停，不經PLC連鎖邏輯 | I29: MCC-PLC自動控制
A30: 26 | B30: CHWP | C30: CHWP1-DI-02 | D30: DI | E30: 冰水泵浦#1 運轉/故障回授 | F30: 無電位接點 | G30: 馬達啟動器/VFD | H30: 兩模式皆回授 | I30: 兩模式皆回授
A31: 27 | B31: CHWP | C31: CHWP1-DO-01 | D31: DO | E31: 冰水泵浦#1 啟動/停止指令 | F31: 24VDC接點輸出 | G31: 馬達啟動器/VFD | H31: 無效(手動模式下由現場按鈕直接控制) | I31: PLC依開機程序(延時啟動)自動下達 | J31: 冷卻水流量確認ON後延時10~30秒啟動
A32: 28 | B32: CHWP | C32: CHWP1-AI-01 | D32: AI | E32: 冰水泵浦#1 VFD頻率/電流回授 | F32: 4-20mA或Modbus | G32: 變頻器 | H32: 監視 | I32: 監視
A33: 29 | B33: CHWP | C33: CHWP1-AI-02 | D33: AI | E33: 冰水泵浦#1 出口壓力 | F33: 4-20mA | G33: 壓力傳訊器 | H33: 監視 | I33: 監視
A34: 30 | B34: CHWP | C34: CHWP1-AO-01 | D34: AO | E34: 冰水泵浦#1 VFD頻率指令 | F34: 4-20mA或Modbus | G34: MCC-PLC→變頻器 | H34: 無效(手動模式由VFD面板設定) | I34: PLC依定壓差或變流量邏輯自動運算輸出 | J34: 部分負載時降低泵浦耗電
A35: 31 | B35: CHWP | C35: CHWP2-DI-01 | D35: DI | E35: 冰水泵浦#2 手動/自動選擇開關位置 | F35: 無電位接點 | G35: 盤面HOA選擇開關 | H35: 現場手動直接啟停，不經PLC連鎖邏輯 | I35: MCC-PLC自動控制
A36: 32 | B36: CHWP | C36: CHWP2-DI-02 | D36: DI | E36: 冰水泵浦#2 運轉/故障回授 | F36: 無電位接點 | G36: 馬達啟動器/VFD | H36: 兩模式皆回授 | I36: 兩模式皆回授
A37: 33 | B37: CHWP | C37: CHWP2-DO-01 | D37: DO | E37: 冰水泵浦#2 啟動/停止指令 | F37: 24VDC接點輸出 | G37: 馬達啟動器/VFD | H37: 無效(手動模式下由現場按鈕直接控制) | I37: PLC依開機程序(延時啟動)自動下達 | J37: 冷卻水流量確認ON後延時10~30秒啟動
A38: 34 | B38: CHWP | C38: CHWP2-AI-01 | D38: AI | E38: 冰水泵浦#2 VFD頻率/電流回授 | F38: 4-20mA或Modbus | G38: 變頻器 | H38: 監視 | I38: 監視
A39: 35 | B39: CHWP | C39: CHWP2-AI-02 | D39: AI | E39: 冰水泵浦#2 出口壓力 | F39: 4-20mA | G39: 壓力傳訊器 | H39: 監視 | I39: 監視
A40: 36 | B40: CHWP | C40: CHWP2-AO-01 | D40: AO | E40: 冰水泵浦#2 VFD頻率指令 | F40: 4-20mA或Modbus | G40: MCC-PLC→變頻器 | H40: 無效(手動模式由VFD面板設定) | I40: PLC依定壓差或變流量邏輯自動運算輸出 | J40: 部分負載時降低泵浦耗電
A41: 37 | B41: CHWP | C41: CHWP-DI-91 | D41: DI | E41: 冰水流量開關 | F41: 無電位接點 | G41: 管路流量開關 | H41: 兩模式皆連鎖生效 | I41: 兩模式皆連鎖生效 | J41: 斷訊時立即連鎖停機並發出警報
...
